Workbook

Sheet Students
A1: student_id | B1: full_name | C1: gender | D1: date_of_birth | E1: email | F1: phone | G1: program | H1: major | I1: department | J1: year_of_study | K1: gpa | L1: credit_hours_earned | M1: status | N1: nationality | O1: enrollment_date | P1: expected_graduation | Q1: Student Type | R1: Programme Level | S1: Journey Stage | T1: Current Semester | U1: Fees Status | V1: Fees Balance (KES) | W1: Academic Standing | X1: Last Standing Review | Y1: Dissertation Title | Z1: Dissertation Status | AA1: Graduation Clearance | AB1: Actual Graduation Date | AC1: Programme Advisor / Supervisor | AD1: Co-Supervisor | AE1: Specialisation / Research Area | AF1: Expected Defense / Completion | AG1: Milestones Achieved | AH1: Next Milestone | AI1: Research / Capstone Output | AJ1: Institution | AK1: NSFAS Beneficiary | AL1: Has Disability | AM1: Disability Type | AN1: Disability Accommodation Needed
A2: TU-2021-0001 | B2: Amelia Odhiambo | C2: Female | D2: 2001-03-12 | E2: a.odhiambo@templumis.ac | F2: +254712345001 | G2: BSc | H2: Computer Science | I2: School of Computing | J2: Year 3 | K2: 3.78 | L2: 96 | M2: Active | N2: Kenyan | O2: 2021-09-05 | P2: 2025-06-30 | Q2: Undergraduate | R2: BSc | S2: 3. Progressing — Year 3 | T2: Sem 6 | U2: Paid | V2: 0 | W2: Good Standing | X2: 2024-01-15 | Y2: N/A | Z2: N/A | AA2: Not Yet | AJ2: Templumis University | AK2: No | AL2: No | AM2: None | AN2: None
A3: TU-2022-0002 | B3: Brian Mwangi | C3: Male | D3: 2002-07-22 | E3: b.mwangi@templumis.ac | F3: +254712345002 | G3: BA | H3: Economics | I3: School of Business | J3: Year 2 | K3: 3.12 | L3: 64 | M3: Active | N3: Kenyan | O3: 2022-09-05 | P3: 2026-06-30 | Q3: Undergraduate | R3: BA | S3: 2. Progressing — Year 2 | T3: Sem 4 | U3: Paid | V3: 0 | W3: Good Standing | X3: 2024-01-15 | Y3: N/A | Z3: N/A | AA3: Not Yet | AJ3: Templumis University | AK3: No | AL3: No | AM3: None | AN3: None
A4: TU-2020-0003 | B4: Claire Nakato | C4: Female | D4: 2000-11-05 | E4: c.nakato@templumis.ac | F4: +256712345003 | G4: BSc | H4: Civil Engineering | I4: School of Engineering | J4: Year 4 | K4: 3.55 | L4: 128 | M4: Active | N4: Ugandan | O4: 2020-09-07 | P4: 2024-06-30 | Q4: Undergraduate | R4: BSc | S4: 4. Final Year — Pre-Clearance | T4: Sem 8 | U4: Paid | V4: 0 | W4: Good Standing | X4: 2024-01-15 | Y4: N/A | Z4: N/A | AA4: In Progress | AJ4: Templumis University | AK4: No | AL4: Yes | AM4: Physical / Mobility Impairment | AN4: Ground-floor lecture venues; extended assignment deadlines
A5: TU-2019-0004 | B5: David Mensah | C5: Male | D5: 1999-04-18 | E5: d.mensah@templumis.ac | F5: +233712345004 | G5: BSc | H5: Nursing | I5: School of Health Sciences | J5: Year 4 | K5: 3.9 | L5: 132 | M5: Graduated | N5: Ghanaian | O5: 2019-09-02 | Q5: Undergraduate | R5: BSc | S5: 6. Graduated ✓ | T5: Completed | U5: Cleared | V5: 0 | W5: Cleared | X5: 2024-01-15 | Y5: N/A | Z5: N/A | AA5: Approved | AB5: 2023-11-10 | AJ5: Templumis University | AK5: No | AL5: No | AM5: None | AN5: None
A6: TU-2023-0005 | B6: Esther Wanjiku | C6: Female | D6: 2003-09-30 | E6: e.wanjiku@templumis.ac | F6: +254712345005 | G6: BSc | H6: Mathematics | I6: School of Science | J6: Year 1 | K6: 2.45 | L6: 32 | M6: Probation | N6: Kenyan | O6: 2023-09-04 | P6: 2027-06-30 | Q6: Undergraduate | R6: BSc | S6: ⚠ Academic Review — Probation | T6: Sem 2 | U6: Partial | V6: 35000 | W6: Probation | X6: 2023-12-01 | Y6: N/A | Z6: N/A | AA6: Blocked | AJ6: Templumis University | AK6: No | AL6: No | AM6: None | AN6: None
A7: TU-2021-0006 | B7: Felix Otieno | C7: Male | D7: 2001-01-14 | E7: f.otieno@templumis.ac | F7: +254712345006 | G7: BEd | H7: Education | I7: School of Education | J7: Year 3 | K7: 3.22 | L7: 98 | M7: Active | N7: Kenyan | O7: 2021-09-05 | P7: 2025-06-30 | Q7: Undergraduate | R7: BEd | S7: 3. Progressing — Year 3 | T7: Sem 6 | U7: Paid | V7: 0 | W7: Good Standing | X7: 2024-01-15 | Y7: N/A | Z7: N/A | AA7: Not Yet | AJ7: Templumis University | AK7: No | AL7: No | AM7: None | AN7: None
A8: TU-2022-0007 | B8: Grace Auma | C8: Female | D8: 2002-06-08 | E8: g.auma@templumis.ac | F8: +254712345007 | G8: BSc | H8: Biochemistry | I8: School of Science | J8: Year 2 | K8: 3.68 | L8: 66 | M8: Active | N8: Kenyan | O8: 2022-09-06 | P8: 2026-06-30 | Q8: Undergraduate | R8: BSc | S8: 2. Progressing — Year 2 | T8: Sem 4 | U8: Paid | V8: 0 | W8: Good Standing | X8: 2024-01-15 | Y8: N/A | Z8: N/A | AA8: Not Yet | AJ8: Templumis University | AK8: No | AL8: No | AM8: None | AN8: None
A9: TU-2020-0008 | B9: Hassan Abdi | C9: Male | D9: 2000-12-20 | E9: h.abdi@templumis.ac | F9: +252712345008 | G9: LLB | H9: Law | I9: School of Law | J9: Year 4 | K9: 3.1 | L9: 120 | M9: Active | N9: Somali | O9: 2020-09-07 | P9: 2024-06-30 | Q9: Undergraduate | R9: LLB | S9: 4. Final Year — Pre-Clearance | T9: Sem 8 | U9: Paid | V9: 0 | W9: Good Standing | X9: 2024-01-15 | Y9: N/A | Z9: N/A | AA9: In Progress | AJ9: Templumis University | AK9: No | AL9: No | AM9: None | AN9: None
A10: TU-2021-0009 | B10: Ivy Njeri | C10: Female | D10: 2001-08-03 | E10: i.njeri@templumis.ac | F10: +254712345009 | G10: BComm | H10: Accounting | I10: School of Business | J10: Year 3 | K10: 2.8 | L10: 90 | M10: On Leave | N10: Kenyan | O10: 2021-09-05 | P10: 2025-06-30 | Q10: Undergraduate | R10: BComm | S10: ⏸ Deferred — On Leave | T10: Sem 6 | U10: Deferred | V10: 0 | W10: Good Standing | X10: 2024-01-15 | Y10: N/A | Z10: N/A | AA10: Not Yet | AJ10: Templumis University | AK10: No | AL10: No | AM10: None | AN10: None
A11: TU-2023-0010 | B11: James Kibaki | C11: Male | D11: 2003-02-25 | E11: j.kibaki@templumis.ac | F11: +254712345010 | G11: BSc | H11: Information Technology | I11: School of Computing | J11: Year 1 | K11: 3.4 | L11: 30 | M11: Active | N11: Kenyan | O11: 2023-09-04 | P11: 2027-06-30 | Q11: Undergraduate | R11: BSc | S11: 1. Enrolled & Orientated | T11: Sem 2 | U11: Paid | V11: 0 | W11: Good Standing | X11: 2024-01-15 | Y11: N/A | Z11: N/A | AA11: Not Yet | AJ11: Templumis University | AK11: No | AL11: No | AM11: None | AN11: None
A12: TU-2022-0011 | B12: Kezia Moraa | C12: Female | D12: 2002-10-11 | E12: k.moraa@templumis.ac | F12: +254712345011 | G12: BSc | H12: Environmental Science | I12: School of Science | J12: Year 2 | K12: 3.05 | L12: 60 | M12: Active | N12: Kenyan | O12: 2022-09-06 | P12: 2026-06-30 | Q12: Undergraduate | R12: BSc | S12: 2. Progressing — Year 2 | T12: Sem 4 | U12: Paid | V12: 0 | W12: Good Standing | X12: 2024-01-15 | Y12: N/A | Z12: N/A | AA12: Not Yet | AJ12: Templumis University | AK12: No | AL12: No | AM12: None | AN12: None
A13: TU-2019-0012 | B13: Liam Okonkwo | C13: Male | D13: 1999-05-17 | E13: l.okonkwo@templumis.ac | F13: +234712345012 | G13: BSc | H13: Electrical Engineering | I13: School of Engineering | J13: Year 4 | K13: 2.6 | L13: 124 | M13: Graduated | N13: Nigerian | O13: 2019-09-02 | Q13: Undergraduate | R13: BSc | S13: 6. Graduated ✓ | T13: Completed | U13: Cleared | V13: 0 | W13: Cleared | X13: 2024-01-15 | Y13: N/A | Z13: N/A | AA13: Approved | AB13: 2023-11-10 | AJ13: Templumis University | AK13: No | AL13: No | AM13: None | AN13: None
A14: TU-2021-0013 | B14: Mary Adhiambo | C14: Female | D14: 2001-07-29 | E14: m.adhiambo@templumis.ac | F14: +254712345013 | G14: BA | H14: Sociology | I14: School of Social Sciences | J14: Year 3 | K14: 3.5 | L14: 94 | M14: Active | N14: Kenyan | O14: 2021-09-05 | P14: 2025-06-30 | Q14: Undergraduate | R14: BA | S14: 3. Progressing — Year 3 | T14: Sem 6 | U14: Paid | V14: 0 | W14: Good Standing | X14: 2024-01-15 | Y14: N/A | Z14: N/A | AA14: Not Yet | AJ14: Templumis University | AK14: No | AL14: No | AM14: None | AN14: None
A15: TU-2020-0014 | B15: Noel Kiprotich | C15: Male | D15: 2000-03-06 | E15: n.kiprotich@templumis.ac | F15: +254712345014 | G15: BPharm | H15: Pharmacy | I15: School of Health Sciences | J15: Year 4 | K15: 1.9 | L15: 112 | M15: Suspended | N15: Kenyan | O15: 2020-09-07 | P15: 2024-06-30 | Q15: Undergraduate | R15: BPharm | S15: ⚠ Academic Hold — Suspended | T15: Sem 8 | U15: Overdue | V15: 75000 | W15: Suspended | X15: 2023-12-01 | Y15: N/A | Z15: N/A | AA15: Blocked | AJ15: Templumis University | AK15: No | AL15: No | AM15: None | AN15: None
A16: TU-2023-0015 | B16: Olivia Achieng | C16: Female | D16: 2003-11-15 | E16: o.achieng@templumis.ac | F16: +254712345015 | G16: BA | H16: Communication | I16: School of Arts | J16: Year 1 | K16: 3.82 | L16: 34 | M16: Active | N16: Kenyan | O16: 2023-09-04 | P16: 2027-06-30 | Q16: Undergraduate | R16: BA | S16: 1. Enrolled & Orientated | T16: Sem 2 | U16: Paid | V16: 0 | W16: Good Standing | X16: 2024-01-15 | Y16: N/A | Z16: N/A | AA16: Not Yet | AJ16: Templumis University | AK16: No | AL16: No | AM16: None | AN16: None
A17: TU-2022-0016 | B17: Patrick Owino | C17: Male | D17: 2002-04-02 | E17: p.owino@templumis.ac | F17: +254712345016 | G17: BSc | H17: Statistics | I17: School of Science | J17: Year 2 | K17: 2.95 | L17: 58 | M17: Active | N17: Kenyan | O17: 2022-09-06 | P17: 2026-06-30 | Q17: Undergraduate | R17: BSc | S17: 2. Progressing — Year 2 | T17: Sem 4 | U17: Paid | V17: 0 | W17: Good Standing | X17: 2024-01-15 | Y17: N/A | Z17: N/A | AA17: Not Yet | AJ17: Templumis University | AK17: No | AL17: Yes | AM17: Visual Impairment | AN17: Screen-reader software; extended exam time
A18: TU-2021-0017 | B18: Queenie Mugo | C18: Female | D18: 2001-09-19 | E18: q.mugo@templumis.ac | F18: +254712345017 | G18: BSc | H18: Computer Science | I18: School of Computing | J18: Year 3 | K18: 3.95 | L18: 100 | M18: Active | N18: Kenyan | O18: 2021-09-05 | P18: 2025-06-30 | Q18: Undergraduate | R18: BSc | S18: 3. Progressing — Year 3 | T18: Sem 6 | U18: Paid | V18: 0 | W18: Good Standing | X18: 2024-01-15 | Y18: N/A | Z18: N/A | AA18: Not Yet | AJ18: Templumis University | AK18: No | AL18: No | AM18: None | AN18: None
A19: TU-2020-0018 | B19: Robert Dlamini | C19: Male | D19: 2000-06-23 | E19: r.dlamini@templumis.ac | F19: +268712345018 | G19: BEd | H19: Science Education | I19: School of Education | J19: Year 4 | K19: 3.3 | L19: 118 | M19: Active | N19: Swazi | O19: 2020-09-07 | P19: 2024-06-30 | Q19: Undergraduate | R19: BEd | S19: 4. Final Year — Pre-Clearance | T19: Sem 8 | U19: Paid | V19: 0 | W19: Good Standing | X19: 2024-01-15 | Y19: N/A | Z19: N/A | AA19: In Progress | AJ19: Templumis University | AK19: No | AL19: No | AM19: None | AN19: None
A20: TU-2023-0019 | B20: Sandra Chebet | C20: Female | D20: 2003-01-08 | E20: s.chebet@templumis.ac | F20: +254712345019 | G20: BSc | H20: Nutrition | I20: School of Health Sciences | J20: Year 1 | K20: 3.15 | L20: 28 | M20: Active | N20: Kenyan | O20: 2023-09-04 | P20: 2027-06-30 | Q20: Undergraduate | R20: BSc | S20: 1. Enrolled & Orientated | T20: Sem 2 | U20: Paid | V20: 0 | W20: Good Standing | X20: 2024-01-15 | Y20: N/A | Z20: N/A | AA20: Not Yet | AJ20: Templumis University | AK20: No | AL20: No | AM20: None | AN20: None
A21: TU-2022-0020 | B21: Tunde Adeyemi | C21: Male | D21: 2002-08-14 | E21: t.adeyemi@templumis.ac | F21: +234712345020 | G21: LLB | H21: Law | I21: School of Law | J21: Year 2 | K21: 3.6 | L21: 62 | M21: Active | N21: Nigerian | O21: 2022-09-06 | P21: 2026-06-30 | Q21: Undergraduate | R21: LLB | S21: 2. Progressing — Year 2 | T21: Sem 4 | U21: Paid | V21: 0 | W21: Good Standing | X21: 2024-01-15 | Y21: N/A | Z21: N/A | AA21: Not Yet | AJ21: Templumis University | AK21: No | AL21: No | AM21: None | AN21: None
A22: TU-2021-0021 | B22: Uchenna Eze | C22: Male | D22: 2001-12-01 | E22: u.eze@templumis.ac | F22: +234712345021 | G22: BA | H22: Political Science | I22: School of Social Sciences | J22: Year 3 | K22: 2.75 | L22: 88 | M22: On Leave | N22: Nigerian | O22: 2021-09-05 | P22: 2025-06-30 | Q22: Undergraduate | R22: BA | S22: ⏸ Deferred — On Leave | T22: Sem 6 | U22: Deferred | V22: 0 | W22: Good Standing | X22: 2024-01-15 | Y22: N/A | Z22: N/A | AA22: Not Yet | AJ22: Templumis University | AK22: No | AL22: No | AM22: None | AN22: None
A23: TU-2019-0022 | B23: Vivian Kamau | C23: Female | D23: 1999-07-27 | E23: v.kamau@templumis.ac | F23: +254712345022 | G23: BSc | H23: Biochemistry | I23: School of Science | J23: Year 4 | K23: 3.88 | L23: 134 | M23: Graduated | N23: Kenyan | O23: 2019-09-02 | Q23: Undergraduate | R23: BSc | S23: 6. Graduated ✓ | T23: Completed | U23: Cleared | V23: 0 | W23: Cleared | X23: 2024-01-15 | Y23: N/A | Z23: N/A | AA23: Approved | AB23: 2023-11-10 | AJ23: Templumis University | AK23: No | AL23: No | AM23: None | AN23: None
A24: TU-2023-0023 | B24: William Barasa | C24: Male | D24: 2003-05-10 | E24: w.barasa@templumis.ac | F24: +254712345023 | G24: BComm | H24: Finance | I24: School of Business | J24: Year 1 | K24: 2.2 | L24: 26 | M24: Probation | N24: Kenyan | O24: 2023-09-04 | P24: 2027-06-30 | Q24: Undergraduate | R24: BComm | S24: ⚠ Academic Review — Probation | T24: Sem 2 | U24: Partial | V24: 35000 | W24: Probation | X24: 2023-12-01 | Y24: N/A | Z24: N/A | AA24: Blocked | AJ24: Templumis University | AK24: No | AL24: No | AM24: None | AN24: None
A25: TU-2022-0024 | B25: Xena Mutua | C25: Female | D25: 2002-02-18 | E25: x.mutua@templumis.ac | F25: +254712345024 | G25: BSc | H25: Information Technology | I25: School of Computing | J25: Year 2 | K25: 3.42 | L25: 68 | M25: Active | N25: Kenyan | O25: 2022-09-06 | P25: 2026-06-30 | Q25: Undergraduate | R25: BSc | S25: 2. Progressing — Year 2 | T25: Sem 4 | U25: Paid | V25: 0 | W25: Good Standing | X25: 2024-01-15 | Y25: N/A | Z25: N/A | AA25: Not Yet | AJ25: Templumis University | AK25: No | AL25: No | AM25: None | AN25: None
A26: TU-2023-0025 | B26: Stephen Gaita Gaikia | C26: Male | D26: 2003-06-17 | E26: s.gaikia@templumis.ac | F26: +254712345025 | G26: BSc | H26: Computer Science | I26: School of Computing | J26: Year 1 | K26: 3.65 | L26: 32 | M26: Active | N26: Kenyan | O26: 2023-09-04 | P26: 2027-06-30 | Q26: Undergraduate | R26: BSc | S26: 1. Enrolled & Orientated | T26: Sem 2 | U26: In Arrears | V26: 75000 | W26: Good Standing | X26: 2024-01-15 | Y26: N/A | Z26: N/A | AA26: Not Yet | AJ26: Templumis University | AK26: No | AL26: No | AM26: None | AN26: None
A27: TU-PG-2022-0026 | B27: Amara Diallo | C27: Female | D27: 1996-03-15 | E27: a.diallo@templumis.ac | F27: +221712345026 | G27: MSc | H27: Data Science | I27: School of Computing | J27: Year 2 | K27: 3.72 | L27: 48 | M27: Active | N27: Senegalese | O27: 2022-09-05 | P27: 2024-06-30 | Q27: Postgraduate | R27: MSc (Coursework) | S27: 3. PG Final Semester — Pre-Graduation | T27: Sem 4 | U27: Paid | V27: 0 | W27: Good Standing | X27: 2024-01-15 | Y27: N/A | Z27: N/A | AA27: In Progress | AC27: Ms. Cynthia Aluoch | AD27: Dr. Kevin Otiato (JKUAT, External) | AE27: Data Science — Urban Mobility & Smart City Analytics | AF27: 45473 | AG27: Coursework Yr1 ✓ | Yr2 ✓ | Capstone Proposal Approved ✓ | Data Analysis In Progress | AH27: Final Capstone Report Submission | AI27: N/A (Coursework Track) | AJ27: Templumis University | AK27: No | AL27: No | AM27: None | AN27: None
A28: TU-PG-2023-0027 | B28: Benjamin Kamto | C28: Male | D28: 1994-07-22 | E28: b.kamto@templumis.ac | F28: +237712345027 | G28: MBA | H28: Business Administration | I28: School of Business | J28: Year 1 | K28: 3.41 | L28: 24 | M28: Active | N28: Cameroonian | O28: 2023-09-04 | P28: 2025-06-30 | Q28: Postgraduate | R28: MBA (Coursework) | S28: 1. PG Enrolled — Coursework Phase | T28: Sem 2 | U28: Paid | V28: 0 | W28: Good Standing | X28: 2024-01-15 | Y28: N/A | Z28: N/A | AA28: Not Yet | AC28: Prof. Wambua Simiyu | AD28: N/A | AE28: MBA — Marketing Analytics & Consumer Behaviour | AF28: 45838 | AG28: Orientation ✓ | Semester 1 Coursework ✓ | AH28: Semester 2 Coursework Completion | AI28: N/A (Coursework Phase) | AJ28: Templumis University | AK28: No | AL28: No | AM28: None | AN28: None
A29: TU-PG-2022-0028 | B29: Celestine Awino | C29: Female | D29: 1995-11-05 | E29: c.awino@templumis.ac | F29: +254712345028 | G29: MA | H29: Economics | I29: School of Business | J29: Year 2 | K29: 3.55 | L29: 52 | M29: Graduated | N29: Kenyan | O29: 2022-09-05 | Q29: Postgraduate | R29: MA (Coursework) | S29: 4. Graduated ✓ | T29: Completed | U29: Cleared | V29: 0 | W29: Cleared | X29: 2023-11-01 | Y29: N/A | Z29: N/A | AA29: Approved | AB29: 2023-11-10 | AC29: Prof. Wambua Simiyu | AD29: N/A | AE29: MA Economics — International Trade & Regional Integration | AF29: 45971 | AG29: All Milestones Complete ✓ | Capstone Defended ✓ | Graduated | AH29: N/A — Graduated | AI29: Capstone: Kenya's Export Diversification & EAC Trade Agreements (2024) | AJ29: Templumis University | AK29: No | AL29: No | AM29: None | AN29: None
A30: TU-PG-2023-0029 | B30: Derrick Ssempa | C30: Male | D30: 1997-04-18 | E30: d.ssempa@templumis.ac | F30: +256712345029 | G30: MSc | H30: Environmental Science | I30: School of Science | J30: Year 1 | K30: 2.81 | L30: 20 | M30: Probation | N30: Ugandan | O30: 2023-09-04 | P30: 2025-06-30 | Q30: Postgraduate | R30: MSc (Coursework) | S30: ⚠ Academic Review — Probation | T30: Sem 2 | U30: Partial | V30: 35000 | W30: Probation | X30: 2023-12-01 | Y30: N/A | Z30: N/A | AA30: Blocked | AC30: Dr. Sasha Mutinda | AD30: N/A | AE30: MSc Environmental Science — Climate Change & Sustainability | AF30: 46022 | AG30: Orientation ✓ | Semester 1 Completed (Probation) | AH30: Semester 2 — Achieve GPA ≥ 3.00 to Continue Programme | AI30: N/A — Academic Review Phase | AJ30: Templumis University | AK30: No | AL30: No | AM30: None | AN30: None
A31: TU-PG-2022-0030 | B31: Faith Onyango | C31: Female | D31: 1996-09-30 | E31: f.onyango@templumis.ac | F31: +254712345030 | G31: MA | H31: Communication | I31: School of Arts | J31: Year 2 | K31: 3.65 | L31: 46 | M31: Active | N31: Kenyan | O31: 2022-09-05 | P31: 2024-06-30 | Q31: Postgraduate | R31: MA (Coursework) | S31: 3. PG Final Semester — Pre-Graduation | T31: Sem 4 | U31: Paid | V31: 0 | W31: Good Standing | X31: 2024-01-15 | Y31: N/A | Z31: N/A | AA31: In Progress | AC31: Ms. Abigael Ndungu | AD31: Dr. Zawadi Amani (School of Social Sciences) | AE31: MA Communication — Digital Media & Political Engagement in Africa | AF31: 45473 | AG31: Coursework Yr1 ✓ | Yr2 ✓ | Capstone Proposal Approved ✓ | AH31: Final Capstone Report Submission | AI31: N/A (Coursework Track) | AJ31: Templumis University | AK31: No | AL31: No | AM31: None | AN31: None
A32: TU-PG-2023-0031 | B32: George Nkosi | C32: Male | D32: 1993-02-14 | E32: g.nkosi@templumis.ac | F32: +27712345031 | G32: MBA | H32: Strategic Management | I32: School of Business | J32: Year 1 | K32: 3.22 | L32: 24 | M32: Active | N32: South African | O32: 2023-09-04 | P32: 2025-06-30 | Q32: Postgraduate | R32: MBA (Coursework) | S32: 1. PG Enrolled — Coursework Phase | T32: Sem 2 | U32: Paid | V32: 0 | W32: Good Standing | X32: 2024-01-15 | Y32: N/A | Z32: N/A | AA32: Not Yet | AC32: Prof. Wambua Simiyu | AD32: N/A | AE32: MBA — Strategic Management & Organisational Leadership | AF32: 45838 | AG32: Orientation ✓ | Semester 1 Coursework ✓ | AH32: Semester 2 Coursework + Capstone Topic Selection | AI32: N/A (Coursework Phase) | AJ32: Templumis University | AK32: No | AL32: No | AM32: None | AN32: None
A33: TU-PG-2021-0032 | B33: Helen Mutuku | C33: Female | D33: 1995-07-03 | E33: h.mutuku@templumis.ac | F33: +254712345032 | G33: MSc by Research | H33: Biochemistry | I33: School of Science | J33: Year 3 | K33: 3.82 | L33: 36 | M33: Active | N33: Kenyan | O33: 2021-09-06 | P33: 2024-06-30 | Q33: Postgraduate | R33: MSc by Research | S33: 4. Thesis Writing Phase | T33: Research Year 3 | U33: Paid | V33: 0 | W33: Good Standing | X33: 2024-01-15 | Y33: Novel Enzyme Inhibitors in Malaria Parasite Metabolism | Z33: Writing | AA33: Not Yet | AC33: Prof. Margaret Wangari | AD33: Dr. Daniel Njomo (KEMRI, External) | AE33: MSc Biochemistry — Antimalarial Drug Discovery & Enzyme Inhibition | AF33: 45463 | AG33: Registered ✓ | Lit Review ✓ | Lab Work ✓ | Analysis ✓ | ⚠ CHALLENGE: Ch.3 Major Revision Required — Kinetic Model Error | Chs 1–2 Supervisor-Approved | AH33: ⚠ CASE-PG-001 ACTIVE: (1) Re-run Ch.3 kinetics using Hill Equation (not Michaelis-Menten) | (2) Secure interim co-supervisor (Dr. Ouma) | (3) Rebook LC-MS/MS (March 2024) | Revised viva: Oct 2024 | AI33: Conference Paper: E. Africa Biochem Symposium 2024 | ⚠ Viva postponed June → October 2024 due to Ch.3 major revision requirement | AJ33: Templumis University | AK33: No | AL33: No | AM33: None | AN33: None
A34: TU-PG-2022-0033 | B34: Ibrahim Hassan | C34: Male | D34: 1996-12-20 | E34: i.hassan@templumis.ac | F34: +251712345033 | G34: MSc by Research | H34: Computer Science | I34: School of Computing | J34: Year 2 | K34: 3.61 | L34: 24 | M34: Active | N34: Ethiopian | O34: 2022-09-05 | P34: 2025-06-30 | Q34: Postgraduate | R34: MSc by Research | S34: 3. Data Collection & Analysis Phase | T34: Research Year 2 | U34: Paid | V34: 0 | W34: Good Standing | X34: 2024-01-15 | Y34: AI-Based Crop Disease Detection Using UAV Imagery | Z34: Data Collection | AA34: Not Yet | AC34: Dr. Kamande Njoroge | AD34: Prof. James Mwema (School of Engineering) | AE34: MSc CS — Computer Vision & Precision Agriculture (UAV-Based Systems) | AF34: 45792 | AG34: Registered ✓ | Lit Review ✓ | ⚠ CHALLENGE: UAV Dataset 31% Unusable (345/500 images valid) | CNN Model Training PAUSED — Dataset rebuild + ethics amendment required | AH34: ⚠ CASE-PG-002 ACTIVE: (1) Ethics amendment: expand to Kakamega & Meru counties | (2) Recollect ≥700 images per revised UAV protocol | (3) Add YOLOv8/EfficientDet/ViT baselines + ablation study for paper revision | AI34: ⚠ AAAI Africa 2025 paper: Major Revisions Required — resubmitting to IEEE Access / CVPR Africa after dataset rebuild | Revised completion: November 2025 | AJ34: Templumis University | AK34: No | AL34: No | AM34: None | AN34: None
A35: TU-PG-2021-0034 | B35: Janet Akinyi | C35: Female | D35: 1994-08-11 | E35: j.akinyi@templumis.ac | F35: +254712345034 | G35: MA by Research | H35: Education | I35: School of Education | J35: Year 3 | K35: 3.48 | L35: 36 | M35: Active | N35: Kenyan | O35: 2021-09-06 | P35: 2024-06-30 | Q35: Postgraduate | R35: MA by Research | S35: 4. Thesis Writing Phase | T35: Research Year 3 | U35: Paid | V35: 0 | W35: Good Standing | X35: 2024-01-15 | Y35: Digital Pedagogy & Learning Outcomes in Kenyan Secondary Schools | Z35: Writing | AA35: Not Yet | AC35: Mr. Barasa Wekesa | AD35: Prof. Agnes Njeru (Ministry of Education, External) | AE35: MA Education — EdTech & Learning Outcomes in Kenyan Secondary Schools | AF35: 45534 | AG35: Registered ✓ | Literature Review ✓ | Fieldwork (12 schools) ✓ | Data Analysis ✓ | Chapters 1–4 Complete ✓ | AH35: Chapter 5 (Conclusions) + Final Submission (Target: August 2024) | AI35: Policy Brief submitted to Kenya Ministry of Education (February 2024) | AJ35: Templumis University | AK35: No | AL35: No | AM35: None | AN35: None
A36: TU-PG-2022-0035 | B36: Kenneth Osei | C36: Male | D36: 1995-05-17 | E36: k.osei@templumis.ac | F36: +233712345035 | G36: MSc by Research | H36: Mechanical Engineering | I36: School of Engineering | J36: Year 2 | K36: 3.31 | L36: 18 | M36: On Leave | N36: Ghanaian | O36: 2022-09-05 | P36: 2026-06-30 | Q36: Postgraduate | R36: MSc by Research | S36: ⏸ Deferred — On Leave (Research) | T36: Research Year 2 | U36: Deferred | V36: 0 | W36: Good Standing | X36: 2024-01-15 | Y36: Low-Cost Solar Desalination for Rural East Africa | Z36: Proposal Approved | AA36: Not Yet | AC36: Dr. Oloo Otiende | AD36: Dr. Marcus Kipande (University of Nairobi, External) | AE36: MSc Mechanical Engineering — Renewable Energy Systems & Rural Water Security | AF36: 46203 | AG36: Registered ✓ | Literature Review ✓ | Research Proposal Approved ✓ | AH36: Return from Leave (Est. Sep 2024) & Begin Prototype Development | AI36: N/A — On Leave; No Research Output Yet | AJ36: Templumis University | AK36: No | AL36: No | AM36: None | AN36: None
A37: TU-PG-2020-0036 | B37: Lydia Cheptoo | C37: Female | D37: 1993-06-23 | E37: l.cheptoo@templumis.ac | F37: +254712345036 | G37: MSc by Research | H37: Public Health | I37: School of Health Sciences | J37: Year 4 | K37: 3.91 | L37: 48 | M37: Graduated | N37: Kenyan | O37: 2020-09-07 | Q37: Postgraduate | R37: MSc by Research | S37: 6. Graduated ✓ (Research) | T37: Completed | U37: Cleared | V37: 0 | W37: Cleared | X37: 2023-11-01 | Y37: Community-Based Interventions for Maternal Health in Western Kenya | Z37: Defended & Approved | AA37: Approved | AB37: 2023-11-10 | AC37: Dr. Atieno Ouma | AD37: Prof. Grace Adhola (WHO Kenya, External) | AE37: MSc Public Health — Maternal & Child Health Interventions in SSA | AF37: 45915 | AG37: All Milestones Complete ✓ | Thesis Defended & Approved ✓ | Graduated | AH37: N/A — Graduated | AI37: Published: East African Medical Journal, 2025 (Vol. 102, Issue 3) | AJ37: Templumis University | AK37: No | AL37: No | AM37: None | AN37: None
A38: TU-PG-2023-0037 | B38: Moses Waweru | C38: Male | D38: 1997-01-08 | E38: m.waweru@templumis.ac | F38: +254712345037 | G38: MSc by Research | H38: Computer Science | I38: School of Computing | J38: Year 1 | K38: 3.52 | L38: 12 | M38: Active | N38: Kenyan | O38: 2023-09-04 | P38: 2026-06-30 | Q38: Postgraduate | R38: MSc by Research | S38: 2. Research Proposal Phase | T38: Research Year 1 | U38: Paid | V38: 0 | W38: Good Standing | X38: 2024-01-15 | Y38: Machine Learning for Swahili NLP Applications | Z38: Proposal Submitted | AA38: Not Yet | AC38: Dr. Kamande Njoroge | AD38: Ms. Cynthia Aluoch | AE38: MSc CS — Natural Language Processing for African Languages (Swahili) | AF38: 46203 | AG38: Registered ✓ | Topic Selection ✓ | Proposal Submitted (Pending Departmental Review) | AH38: Proposal Defense & Ethics Clearance (Target: April 2024) | AI38: N/A — Early Stage Research (Year 1) | AJ38: Templumis University | AK38: No | AL38: No | AM38: None | AN38: None
A39: TU-PHD-2021-0038 | B39: Amina Osei | C39: Female | D39: 33465 | E39: a.osei@templumis.ac | F39: +233712345038 | G39: PhD | H39: Computer Science | I39: School of Computing | J39: Year 3 | K39: 3.88 | L39: 36 | M39: Active | N39: Ghanaian | O39: 45175 | P39: 46203 | Q39: Postgraduate | R39: PhD by Research | S39: 5. Candidacy Confirmed — Data Collection Phase | T39: Research Year 3 | U39: Paid | V39: 0 | W39: Good Standing | X39: 45306 | Y39: Federated Learning for Privacy-Preserving Health Data Analytics in Sub-Saharan Africa | Z39: Data Collection | AA39: Not Yet | AC39: Dr. Kamande Njoroge | AD39: Prof. Ruth Mutua (Strathmore University, External) | AE39: Computer Science — Federated Learning, Privacy & mHealth in Africa | AF39: 46142 | AG39: Enrolled ✓ | Foundation CW ✓ | Proposal Defended ✓ | Candidacy Confirmed ✓ | FL Architecture Designed ✓ | Data Collection Ongoing (4 hospital sites) | AH39: Complete Hospital Data Collection & Begin Federated Model Training | AI39: Poster: African AI Summit 2024 | Working Paper: IEEE Trans. Medical Informatics (under review) | AJ39: Templumis University | AK39: No | AL39: No | AM39: None | AN39: None
A40: TU-PHD-2020-0039 | B40: Samuel Odhiambo | C40: Male | D40: 32954 | E40: s.odhiambo@templumis.ac | F40: +254712345039 | G40: PhD | H40: Public Health | I40: School of Health Sciences | J40: Year 4 | K40: 3.71 | L40: 48 | M40: Active | N40: Kenyan | O40: 45176 | P40: 46203 | Q40: Postgraduate | R40: PhD by Research | S40: 6. Thesis Writing Phase (Final) | T40: Research Year 4 | U40: Paid | V40: 0 | W40: Good Standing | X40: 45306 | Y40: Impact of Community Health Worker Integration on Under-5 Mortality Rates in Rural Kenya | Z40: Writing | AA40: Pending | AC40: Dr. Atieno Ouma | AD40: Dr. Rebecca Adero (WHO Kenya, External) | AE40: Public Health — Community Health Systems, Child Survival & Rural Health Delivery | AF40: 45930 | AG40: Enrolled ✓ | Foundation CW ✓ | Proposal Defended ✓ | Candidacy Confirmed ✓ | Fieldwork (14 counties, n=2,400) ✓ | Data Analysis ✓ | Chapters 1–4 Approved ✓ | AH40: Complete Chapter 5 (Conclusions & Policy Recommendations) + Submit Full Thesis Draft | AI40: Published: African J. Primary Health Care (2024) | Under Review: PLOS Global Health | AJ40: Templumis University | AK40: No | AL40: No | AM40: None | AN40: None
...

Sheet Courses
A1: course_code | B1: title | C1: department | D1: instructor | E1: credits | F1: enrolled_count | G1: type | H1: schedule | I1: room | J1: status | K1: Institution
A2: CS301 | B2: Data Structures & Algorithms | C2: School of Computing | D2: Dr. Kamande Njoroge | E2: 4 | F2: 18 | G2: Core | H2: Mon/Wed 8–10am | I2: LH-201 | J2: Active | K2: Templumis University
A3: CS201 | B3: Object-Oriented Programming | C3: School of Computing | D3: Dr. Kamande Njoroge | E3: 3 | F3: 22 | G3: Core | H3: Tue/Thu 10–12pm | I3: LH-202 | J3: Active | K3: Templumis University
A4: ECO201 | B4: Microeconomics | C4: School of Business | D4: Prof. Wambua Simiyu | E4: 3 | F4: 35 | G4: Core | H4: Mon/Wed 2–4pm | I4: BH-101 | J4: Active | K4: Templumis University
A5: ACC301 | B5: Intermediate Accounting | C5: School of Business | D5: Ms. Ruth Kariuki | E5: 4 | F5: 28 | G5: Core | H5: Tue/Thu 8–10am | I5: BH-102 | J5: Active | K5: Templumis University
A6: CE401 | B6: Structural Engineering | C6: School of Engineering | D6: Dr. Oloo Otiende | E6: 4 | F6: 15 | G6: Core | H6: Mon 8–12pm | I6: EH-301 | J6: Active | K6: Templumis University
A7: EE401 | B7: Power Systems | C7: School of Engineering | D7: Prof. James Mwema | E7: 4 | F7: 12 | G7: Core | H7: Wed 8–12pm | I7: EH-302 | J7: Active | K7: Templumis University
A8: LAW301 | B8: Contract Law | C8: School of Law | D8: Prof. Adhiambo Orengo | E8: 4 | F8: 20 | G8: Core | H8: Tue/Thu 2–4pm | I8: LW-101 | J8: Active | K8: Templumis University
A9: BCH201 | B9: Biochemistry I | C9: School of Science | D9: Dr. Mwangi Kiarie | E9: 3 | F9: 24 | G9: Core | H9: Mon/Wed 10–12pm | I9: SC-201 | J9: Active | K9: Templumis University
A10: NUR301 | B10: Clinical Nursing Practice | C10: School of Health Sciences | D10: Dr. Atieno Ouma | E10: 5 | F10: 18 | G10: Core | H10: Fri 8am–2pm | I10: HS-401 | J10: Active | K10: Templumis University
A11: EDU201 | B11: Curriculum Development | C11: School of Education | D11: Mr. Barasa Wekesa | E11: 3 | F11: 20 | G11: Core | H11: Tue/Thu 12–2pm | I11: ED-101 | J11: Active | K11: Templumis University
A12: SOC201 | B12: Sociological Theory | C12: School of Social Sciences | D12: Dr. Zawadi Amani | E12: 3 | F12: 26 | G12: Core | H12: Mon/Wed 12–2pm | I12: SS-101 | J12: Active | K12: Templumis University
A13: COM101 | B13: Introduction to Mass Media | C13: School of Arts | D13: Ms. Abigael Ndungu | E13: 3 | F13: 30 | G13: Core | H13: Mon/Wed 4–6pm | I13: AR-101 | J13: Active | K13: Templumis University
... A78: RU-PHD702 | B78: Doctoral Seminar Series | C78: Directorate of Graduate Studies | D78: Prof. Richard Onyango | E78: 1 | F78: 4 | G78: PhD Core | H78: Fri 3–4pm | I78: GS-Seminar | J78: Active | K78: Rongo University

Sheet Enrolments
A1: enrolment_id | B1: student_id | C1: student_name | D1: course_code | E1: course_title | F1: enrol_date | G1: status | H1: midterm_score | I1: current_grade | J1: Institution
A2: ENR-0001 | B2: TU-2021-0001 | C2: Amelia Odhiambo | D2: CS301 | E2: Data Structures & Algorithms | F2: 2023-09-05 | G2: Enrolled | H2: 82 | I2: 85 | J2: Templumis University
A3: ENR-0002 | B3: TU-2021-0001 | C3: Amelia Odhiambo | D3: CS201 | E3: Object-Oriented Programming | F3: 2023-09-05 | G3: Enrolled | H3: 88 | I3: 87 | J3: Templumis University
A4: ENR-0003 | B4: TU-2021-0001 | C4: Amelia Odhiambo | D4: MATH201 | E4: Calculus II | F4: 2023-09-05 | G4: Enrolled | H4: 75 | I4: 78 | J4: Templumis University
A5: ENR-0004 | B5: TU-2021-0001 | C5: Amelia Odhiambo | D5: GEN101 | E5: Communication Skills | F5: 2023-09-05 | G5: Enrolled | H5: 90 | I5: 91 | J5: Templumis University
A6: ENR-0005 | B6: TU-2022-0002 | C6: Brian Mwangi | D6: ECO201 | E6: Microeconomics | F6: 2023-09-05 | G6: Enrolled | H6: 72 | I6: 74 | J6: Templumis University
A7: ENR-0006 | B7: TU-2022-0002 | C7: Brian Mwangi | D7: FIN201 | E7: Principles of Finance | F7: 2023-09-05 | G7: Enrolled | H7: 68 | I7: 70 | J7: Templumis University
A8: ENR-0007 | B8: TU-2022-0002 | C8: Brian Mwangi | D8: MATH201 | E8: Calculus II | F8: 2023-09-05 | G8: Enrolled | H8: 65 | I8: 67 | J8: Templumis University
A9: ENR-0008 | B9: TU-2022-0002 | C9: Brian Mwangi | D9: GEN101 | E9: Communication Skills | F9: 2023-09-05 | G9: Enrolled | H9: 78 | I9: 77 | J9: Templumis University
A10: ENR-0009 | B10: TU-2020-0003 | C10: Claire Nakato | D10: CE401 | E10: Structural Engineering | F10: 2023-09-07 | G10: Enrolled | H10: 80 | I10: 82 | J10: Templumis University
A11: ENR-0010 | B11: TU-2020-0003 | C11: Claire Nakato | D11: MATH201 | E11: Calculus II | F11: 2023-09-07 | G11: Enrolled | H11: 76 | I11: 78 | J11: Templumis University
A12: ENR-0011 | B12: TU-2020-0003 | C12: Claire Nakato | D12: ENV201 | E12: Environmental Ecology | F12: 2023-09-07 | G12: Enrolled | H12: 83 | I12: 84 | J12: Templumis University
A13: ENR-0012 | B13: TU-2020-0003 | C13: Claire Nakato | D13: GEN101 | E13: Communication Skills | F13: 2023-09-07 | G13: Enrolled | H13: 88 | I13: 89 | J13: Templumis University
... A82: ENR-0081 | B82: TU-2023-0025 | C82: Stephen Gaita Gaikia | D82: GEN101 | E82: Communication Skills | F82: 2023-09-04 | G82: Enrolled | H82: 87 | I82: 88 | J82: Templumis University
A83: ENR-0082 | B83: TU-PG-2022-0026 | C83: Amara Diallo | D83: MSC601 | E83: Advanced Data Science & Machine Learning | F83: 45327 | G83: Enrolled | H83: 81 | I83: 83 | J83: Templumis University
A84: ENR-0083 | B84: TU-PG-2022-0026 | C84: Amara Diallo | D84: PGR602 | E84: Thesis Writing & Scholarly Communication | F84: 45327 | G84: Enrolled | H84: 78 | I84: 80 | J84: Templumis University
A85: ENR-0084 | B85: TU-PG-2022-0026 | C85: Amara Diallo | D85: PGR603 | E85: Graduate Research Colloquium & Seminar | F85: 45327 | G85: Enrolled | H85: 85 | I85: 86 | J85: Templumis University
A86: ENR-0085 | B86: TU-PG-2023-0027 | C86: Benjamin Kamto | D86: MBA601 | E86: Strategic Leadership & Corporate Governance | F86: 45306 | G86: Enrolled | H86: 74 | I86: 76 | J86: Templumis University
A87: ENR-0086 | B87: TU-PG-2023-0027 | C87: Benjamin Kamto | D87: MBA602 | E87: Advanced Financial Management | F87: 45306 | G87: Enrolled | H87: 70 | I87: 72 | J87: Templumis University
A88: ENR-0087 | B88: TU-PG-2023-0027 | C88: Benjamin Kamto | D88: MBA603 | E88: Innovation, Entrepreneurship & Strategy | F88: 45306 | G88: Enrolled | H88: 77 | I88: 79 | J88: Templumis University
A89: ENR-0088 | B89: TU-PG-2023-0027 | C89: Benjamin Kamto | D89: PGR603 | E89: Graduate Research Colloquium & Seminar | F89: 45306 | G89: Enrolled | H89: 72 | I89: 74 | J89: Templumis University
A90: ENR-0089 | B90: TU-PG-2023-0029 | C90: Derrick Ssempa | D90: MSC602 | E90: Advanced Environmental Research Methods | F90: 45306 | G90: Enrolled | H90: 55 | I90: 58 | J90: Templumis University
A91: ENR-0090 | B91: TU-PG-2023-0029 | C91: Derrick Ssempa | D91: PGR601 | E91: Research Methods & Academic Writing | F91: 45306 | G91: Enrolled | H91: 60 | I91: 62 | J91: Templumis University
A92: ENR-0091 | B92: TU-PG-2022-0030 | C92: Faith Onyango | D92: PGR602 | E92: Thesis Writing & Scholarly Communication | F92: 45327 | G92: Enrolled | H92: 80 | I92: 82 | J92: Templumis University
A93: ENR-0092 | B93: TU-PG-2022-0030 | C93: Faith Onyango | D93: PGR603 | E93: Graduate Research Colloquium & Seminar | F93: 45327 | G93: Enrolled | H93: 84 | I93: 85 | J93: Templumis University
A94: ENR-0093 | B94: TU-PG-2023-0031 | C94: George Nkosi | D94: MBA601 | E94: Strategic Leadership & Corporate Governance | F94: 45306 | G94: Enrolled | H94: 71 | I94: 73 | J94: Templumis University
... A115: ENR-0114 | B115: TU-PHD-2020-0039 | C115: Samuel Odhiambo | D115: PGR602 | E115: Thesis Writing & Scholarly Communication | F115: 45301 | G115: Enrolled | H115: 91 | I115: 93 | J115: Templumis University
A116: ENR-0115 | B116: KT-2021-0001 | C116: Yusuf Al-Farsi | D116: KT-CS101 | E116: Introduction to Programming | F116: 2023-09-05 | G116: Enrolled | H116: 92 | I116: 95 | J116: Kitaptech University
A117: ENR-0116 | B117: KT-2021-0001 | C117: Yusuf Al-Farsi | D117: KT-CS201 | E117: Data Structures & Algorithms | F117: 2023-09-05 | G117: Enrolled | H117: 90 | I117: 93 | J117: Kitaptech University
A118: ENR-0117 | B118: KT-2021-0001 | C118: Yusuf Al-Farsi | D118: KT-MATH201 | E118: Discrete Mathematics | F118: 2023-09-05 | G118: Enrolled | H118: 88 | I118: 91 | J118: Kitaptech University
A119: ENR-0118 | B119: KT-2022-0002 | C119: Fatima Al-Sayed | D119: KT-SE201 | E119: Object-Oriented Software Design | F119: 2023-09-05 | G119: Enrolled | H119: 87 | I119: 85 | J119: Kitaptech University
A120: ENR-0119 | B120: KT-2022-0002 | C120: Fatima Al-Sayed | D120: KT-SE301 | E120: DevOps & Cloud-Native Engineering | F120: 2023-09-05 | G120: Enrolled | H120: 85 | I120: 83 | J120: Kitaptech University
A121: ENR-0120 | B121: KT-2022-0002 | C121: Fatima Al-Sayed | D121: KT-MATH201 | E121: Discrete Mathematics | F121: 2023-09-05 | G121: Enrolled | H121: 83 | I121: 81 | J121: Kitaptech University
A122: ENR-0121 | B122: KT-2020-0003 | C122: Omar Haddad | D122: KT-IT201 | E122: Networks & Systems Administration | F122: 2023-09-05 | G122: Enrolled | H122: 90 | I122: 93 | J122: Kitaptech University
A123: ENR-0122 | B123: KT-2020-0003 | C123: Omar Haddad | D123: KT-IT301 | E123: Cybersecurity Fundamentals | F123: 2023-09-05 | G123: Enrolled | H123: 88 | I123: 91 | J123: Kitaptech University
A124: ENR-0123 | B124: KT-2020-0003 | C124: Omar Haddad | D124: KT-IT302 | E124: Digital Forensics & Incident Response | F124: 2023-09-05 | G124: Enrolled | H124: 86 | I124: 89 | J124: Kitaptech University
A125: ENR-0124 | B125: KT-2020-0004 | C125: Layla Mansour | D125: KT-DS201 | E125: Statistics & Probability for Data Science | F125: 2023-09-05 | G125: Completed | H125: 94 | I125: 97 | J125: Kitaptech University
A126: ENR-0125 | B126: KT-2020-0004 | C126: Layla Mansour | D126: KT-DS301 | E126: Machine Learning Foundations | F126: 2023-09-05 | G126: Completed | H126: 92 | I126: 95 | J126: Kitaptech University
A127: ENR-0126 | B127: KT-2020-0004 | C127: Layla Mansour | D127: KT-DS401 | E127: Deep Learning & Neural Networks | F127: 2023-09-05 | G127: Completed | H127: 90 | I127: 93 | J127: Kitaptech University
... A391: ENR-0390 | B391: TU-PG-2025-0081 | C391: Given Mthembu | D391: MBA602 | E391: Advanced Financial Management | F391: 2025-09-05 | G391: Enrolled | H391: 60 | I391: 60 | J391: Templumis University

Sheet Grades
A1: grade_id | B1: student_id | C1: student_name | D1: course_code | E1: assignment_1 | F1: assignment_2 | G1: midterm | H1: final | I1: total | J1: letter_grade | K1: Institution
A2: GRD-0001 | B2: TU-2021-0001 | C2: Amelia Odhiambo | D2: CS301 | E2: 85 | F2: 88 | G2: 82 | J2: B | K2: Templumis University
A3: GRD-0002 | B3: TU-2021-0001 | C3: Amelia Odhiambo | D3: CS201 | E3: 90 | F3: 87 | G3: 88 | J3: B | K3: Templumis University
A4: GRD-0003 | B4: TU-2021-0001 | C4: Amelia Odhiambo | D4: MATH201 | E4: 78 | F4: 80 | G4: 75 | J4: B | K4: Templumis University
A5: GRD-0004 | B5: TU-2021-0001 | C5: Amelia Odhiambo | D5: GEN101 | E5: 92 | F5: 91 | G5: 90 | J5: A | K5: Templumis University
A6: GRD-0005 | B6: TU-2019-0004 | C6: David Mensah | D6: NUR301 | E6: 94 | F6: 93 | G6: 91 | H6: 95 | I6: 93 | J6: A | K6: Templumis University
A7: GRD-0006 | B7: TU-2019-0004 | C7: David Mensah | D7: BCH201 | E7: 91 | F7: 90 | G7: 88 | H7: 91 | I7: 90 | J7: A | K7: Templumis University
A8: GRD-0007 | B8: TU-2023-0005 | C8: Esther Wanjiku | D8: MATH201 | E8: 52 | F8: 55 | G8: 48 | J8: D | K8: Templumis University
A9: GRD-0008 | B9: TU-2021-0017 | C9: Queenie Mugo | D9: CS301 | E9: 97 | F9: 96 | G9: 95 | J9: A | K9: Templumis University
A10: GRD-0009 | B10: TU-2020-0014 | C10: Noel Kiprotich | D10: BCH201 | E10: 48 | F10: 46 | G10: 45 | J10: F | K10: Templumis University
A11: GRD-0010 | B11: TU-2022-0020 | C11: Tunde Adeyemi | D11: LAW301 | E11: 86 | F11: 85 | G11: 84 | J11: B | K11: Templumis University
A12: GRD-0011 | B12: TU-2023-0015 | C12: Olivia Achieng | D12: COM101 | E12: 91 | F12: 90 | G12: 89 | J12: A | K12: Templumis University
A13: GRD-0012 | B13: TU-2019-0022 | C13: Vivian Kamau | D13: BCH201 | E13: 93 | F13: 92 | G13: 90 | H13: 94 | I13: 93 | J13: A | K13: Templumis University
A14: GRD-0013 | B14: TU-2023-0025 | C14: Stephen Gaita Gaikia | D14: CS101 | E14: 88 | F14: 85 | G14: 84 | J14: B | K14: Templumis University
A15: GRD-0014 | B15: TU-2023-0025 | C15: Stephen Gaita Gaikia | D15: IT201 | E15: 80 | F15: 79 | G15: 78 | J15: B | K15: Templumis University
A16: GRD-0015 | B16: TU-2023-0025 | C16: Stephen Gaita Gaikia | D16: MATH201 | E16: 83 | F16: 82 | G16: 81 | J16: B | K16: Templumis University
A17: GRD-0016 | B17: TU-2023-0025 | C17: Stephen Gaita Gaikia | D17: GEN101 | E17: 89 | F17: 88 | G17: 87 | J17: B | K17: Templumis University
A18: GRD-0017 | B18: TU-PG-2022-0026 | C18: Amara Diallo | D18: MSC601 | E18: 83 | F18: 85 | G18: 81 | J18: B | K18: Templumis University
A19: GRD-0018 | B19: TU-PG-2022-0026 | C19: Amara Diallo | D19: PGR602 | E19: 80 | F19: 82 | G19: 78 | J19: B | K19: Templumis University
A20: GRD-0019 | B20: TU-PG-2022-0026 | C20: Amara Diallo | D20: PGR603 | E20: 88 | F20: 87 | G20: 85 | J20: B | K20: Templumis University
A21: GRD-0020 | B21: TU-PG-2023-0027 | C21: Benjamin Kamto | D21: MBA601 | E21: 76 | F21: 78 | G21: 74 | J21: B | K21: Templumis University
A22: GRD-0021 | B22: TU-PG-2023-0027 | C22: Benjamin Kamto | D22: MBA602 | E22: 72 | F22: 75 | G22: 70 | J22: C | K22: Templumis University
A23: GRD-0022 | B23: TU-PG-2023-0027 | C23: Benjamin Kamto | D23: MBA603 | E23: 79 | F23: 80 | G23: 77 | J23: B | K23: Templumis University
A24: GRD-0023 | B24: TU-PG-2023-0029 | C24: Derrick Ssempa | D24: MSC602 | E24: 58 | F24: 60 | G24: 55 | J24: D | K24: Templumis University
A25: GRD-0024 | B25: TU-PG-2023-0029 | C25: Derrick Ssempa | D25: PGR601 | E25: 62 | F25: 63 | G25: 60 | J25: D | K25: Templumis University
... A51: GRD-0050 | B51: KT-2020-0003 | C51: Omar Haddad | D51: KT-IT201 | E51: 93 | F51: 88 | G51: 90 | J51: A | K51: Kitaptech University
A52: GRD-0051 | B52: KT-2020-0004 | C52: Layla Mansour | D52: KT-DS201 | E52: 97 | F52: 92 | G52: 94 | H52: 97 | I52: 95 | J52: A | K52: Kitaptech University
A53: GRD-0052 | B53: KT-2023-0005 | C53: Khalid Nasser | D53: KT-IT201 | E53: 82 | F53: 77 | G53: 79 | J53: C | K53: Kitaptech University
A54: GRD-0053 | B54: KT-2021-0006 | C54: Rania Saleh | D54: KT-CS101 | E54: 91 | F54: 86 | G54: 88 | J54: B | K54: Kitaptech University
A55: GRD-0054 | B55: KT-2022-0007 | C55: Hamza Zidane | D55: KT-FT201 | E55: 94 | F55: 89 | G55: 91 | J55: A | K55: Kitaptech University
A56: GRD-0055 | B56: KT-2020-0008 | C56: Noor Al-Amin | D56: KT-SE201 | E56: 89 | F56: 84 | G56: 86 | J56: B | K56: Kitaptech University
A57: GRD-0056 | B57: KT-2021-0009 | C57: Bilal Qureshi | D57: KT-DS201 | E57: 85 | F57: 80 | G57: 82 | H57: 80 | I57: 82 | J57: B | K57: Kitaptech University
A58: GRD-0057 | B58: KT-2023-0010 | C58: Sami Hijazi | D58: KT-IT201 | E58: 92 | F58: 87 | G58: 89 | J58: A | K58: Kitaptech University
A59: GRD-0058 | B59: KT-2022-0011 | C59: Dalia Abdullah | D59: KT-CS101 | E59: 88 | F59: 83 | G59: 85 | J59: B | K59: Kitaptech University
A60: GRD-0059 | B60: KT-2020-0012 | C60: Tariq Al-Otaibi | D60: KT-SE201 | E60: 84 | F60: 79 | G60: 81 | H60: 79 | I60: 81 | J60: B | K60: Kitaptech University
A61: GRD-0060 | B61: KT-2021-0013 | C61: Maryam Karam | D61: KT-IT201 | E61: 93 | F61: 88 | G61: 90 | J61: A | K61: Kitaptech University
A62: GRD-0061 | B62: KT-2020-0014 | C62: Faisal Al-Mutairi | D62: KT-FT201 | E62: 77 | F62: 72 | G62: 74 | J62: C | K62: Kitaptech University
A63: GRD-0062 | B63: KT-2023-0015 | C63: Huda Shammari | D63: KT-DS201 | E63: 96 | F63: 91 | G63: 93 | J63: A | K63: Kitaptech University
A64: GRD-0063 | B64: KT-2021-0016 | C64: Ahmed Al-Masri | D64: KT-CS101 | E64: 89 | F64: 84 | G64: 86 | J64: B | K64: Kitaptech University
A65: GRD-0064 | B65: KT-2022-0017 | C65: Yasmin Qasim | D65: KT-IT201 | E65: 94 | F65: 89 | G65: 91 | J65: A | K65: Kitaptech University
...

Sheet Attendance
A1: attendance_id | B1: student_id | C1: student_name | D1: course_code | E1: course_title | F1: total_sessions | G1: present | H1: absent | I1: late | J1: attendance_pct | K1: risk_level | L1: Institution
A2: ATT-0001 | B2: TU-2021-0001 | C2: Amelia Odhiambo | D2: CS301 | E2: Data Structures & Algorithms | F2: 28 | G2: 26 | H2: 2 | I2: 1 | J2: =ROUND(G2/F2*100,0) -> 93 | K2: Good | L2: Templumis University
A3: ATT-0002 | B3: TU-2021-0001 | C3: Amelia Odhiambo | D3: CS201 | E3: Object-Oriented Programming | F3: 26 | G3: 25 | H3: 1 | I3: 2 | J3: =ROUND(G3/F3*100,0) -> 96 | K3: Good | L3: Templumis University
A4: ATT-0003 | B4: TU-2023-0005 | C4: Esther Wanjiku | D4: MATH201 | E4: Calculus II | F4: 30 | G4: 17 | H4: 13 | I4: 3 | J4: =ROUND(G4/F4*100,0) -> 57 | K4: At Risk | L4: Templumis University
A5: ATT-0004 | B5: TU-2020-0014 | C5: Noel Kiprotich | D5: BCH201 | E5: Biochemistry I | F5: 26 | G5: 14 | H5: 12 | I5: 2 | J5: =ROUND(G5/F5*100,0) -> 54 | K5: At Risk | L5: Templumis University
A6: ATT-0005 | B6: TU-2021-0017 | C6: Queenie Mugo | D6: CS301 | E6: Data Structures & Algorithms | F6: 28 | G6: 28 | H6: 0 | I6: 0 | J6: =ROUND(G6/F6*100,0) -> 100 | K6: Good | L6: Templumis University
A7: ATT-0006 | B7: TU-2022-0002 | C7: Brian Mwangi | D7: ECO201 | E7: Microeconomics | F7: 26 | G7: 21 | H7: 5 | I7: 2 | J7: =ROUND(G7/F7*100,0) -> 81 | K7: Good | L7: Templumis University
A8: ATT-0007 | B8: TU-2023-0023 | C8: William Barasa | D8: FIN201 | E8: Principles of Finance | F8: 26 | G8: 16 | H8: 10 | I8: 3 | J8: =ROUND(G8/F8*100,0) -> 62 | K8: Warning | L8: Templumis University
A9: ATT-0008 | B9: TU-2023-0015 | C9: Olivia Achieng | D9: COM101 | E9: Introduction to Mass Media | F9: 24 | G9: 24 | H9: 0 | I9: 1 | J9: =ROUND(G9/F9*100,0) -> 100 | K9: Good | L9: Templumis University
A10: ATT-0009 | B10: TU-2020-0008 | C10: Hassan Abdi | D10: LAW301 | E10: Contract Law | F10: 26 | G10: 22 | H10: 4 | I10: 1 | J10: =ROUND(G10/F10*100,0) -> 85 | K10: Good | L10: Templumis University
A11: ATT-0010 | B11: TU-2021-0009 | C11: Ivy Njeri | D11: ACC301 | E11: Intermediate Accounting | F11: 26 | G11: 16 | H11: 10 | I11: 2 | J11: =ROUND(G11/F11*100,0) -> 62 | K11: Warning | L11: Templumis University
A12: ATT-0011 | B12: TU-2021-0021 | C12: Uchenna Eze | D12: SOC201 | E12: Sociological Theory | F12: 24 | G12: 15 | H12: 9 | I12: 2 | J12: =ROUND(G12/F12*100,0) -> 63 | K12: Warning | L12: Templumis University
A13: ATT-0012 | B13: TU-2022-0024 | C13: Xena Mutua | D13: IT201 | E13: Database Management Systems | F13: 24 | G13: 22 | H13: 2 | I13: 1 | J13: =ROUND(G13/F13*100,0) -> 92 | K13: Good | L13: Templumis University
... A17: ATT-0016 | B17: TU-2023-0025 | C17: Stephen Gaita Gaikia | D17: GEN101 | E17: Communication Skills | F17: 24 | G17: 23 | H17: 1 | I17: 0 | J17: =ROUND(G17/F17*100,0) -> 96 | K17: Good | L17: Templumis University
A18: ATT-0017 | B18: TU-PG-2022-0026 | C18: Amara Diallo | D18: MSC601 | E18: Advanced Data Science & Machine Learning | F18: 24 | G18: 22 | H18: 2 | I18: 1 | J18: 92 | K18: Good | L18: Templumis University
A19: ATT-0018 | B19: TU-PG-2022-0026 | C19: Amara Diallo | D19: PGR602 | E19: Thesis Writing & Scholarly Communication | F19: 20 | G19: 19 | H19: 1 | I19: 1 | J19: 95 | K19: Good | L19: Templumis University
A20: ATT-0019 | B20: TU-PG-2022-0026 | C20: Amara Diallo | D20: PGR603 | E20: Graduate Research Colloquium & Seminar | F20: 16 | G20: 15 | H20: 1 | I20: 0 | J20: 94 | K20: Good | L20: Templumis University
A21: ATT-0020 | B21: TU-PG-2023-0027 | C21: Benjamin Kamto | D21: MBA601 | E21: Strategic Leadership & Corporate Governance | F21: 22 | G21: 19 | H21: 3 | I21: 1 | J21: 86 | K21: Good | L21: Templumis University
A22: ATT-0021 | B22: TU-PG-2023-0027 | C22: Benjamin Kamto | D22: MBA602 | E22: Advanced Financial Management | F22: 22 | G22: 18 | H22: 4 | I22: 1 | J22: 82 | K22: Good | L22: Templumis University
A23: ATT-0022 | B23: TU-PG-2023-0027 | C23: Benjamin Kamto | D23: MBA603 | E23: Innovation, Entrepreneurship & Strategy | F23: 20 | G23: 18 | H23: 2 | I23: 1 | J23: 90 | K23: Good | L23: Templumis University
A24: ATT-0023 | B24: TU-PG-2023-0029 | C24: Derrick Ssempa | D24: MSC602 | E24: Advanced Environmental Research Methods | F24: 22 | G24: 13 | H24: 9 | I24: 2 | J24: 59 | K24: At Risk | L24: Templumis University
A25: ATT-0024 | B25: TU-PG-2023-0029 | C25: Derrick Ssempa | D25: PGR601 | E25: Research Methods & Academic Writing | F25: 18 | G25: 11 | H25: 7 | I25: 2 | J25: 61 | K25: Warning | L25: Templumis University
A26: ATT-0025 | B26: TU-PG-2022-0030 | C26: Faith Onyango | D26: PGR602 | E26: Thesis Writing & Scholarly Communication | F26: 20 | G26: 19 | H26: 1 | I26: 0 | J26: 95 | K26: Good | L26: Templumis University
A27: ATT-0026 | B27: TU-PG-2022-0030 | C27: Faith Onyango | D27: PGR603 | E27: Graduate Research Colloquium & Seminar | F27: 16 | G27: 15 | H27: 1 | I27: 1 | J27: 94 | K27: Good | L27: Templumis University
A28: ATT-0027 | B28: TU-PG-2023-0031 | C28: George Nkosi | D28: MBA601 | E28: Strategic Leadership & Corporate Governance | F28: 22 | G28: 20 | H28: 2 | I28: 0 | J28: 91 | K28: Good | L28: Templumis University
A29: ATT-0028 | B29: TU-PG-2023-0031 | C29: George Nkosi | D29: MBA602 | E29: Advanced Financial Management | F29: 22 | G29: 19 | H29: 3 | I29: 1 | J29: 86 | K29: Good | L29: Templumis University
... A48: ATT-0047 | B48: TU-PHD-2020-0039 | C48: Samuel Odhiambo | D48: PGR602 | E48: Thesis Writing & Scholarly Communication | F48: 20 | G48: 20 | H48: 0 | I48: 0 | J48: 100 | K48: Good | L48: Templumis University
A49: ATT-0048 | B49: KT-2021-0001 | C49: Yusuf Al-Farsi | D49: KT-CS101 | E49: Introduction to Programming | F49: 26 | G49: 25 | H49: 0 | I49: 1 | J49: =ROUND(G49/F49*100,0) -> 96 | K49: Good | L49: Kitaptech University
A50: ATT-0049 | B50: KT-2022-0002 | C50: Fatima Al-Sayed | D50: KT-SE201 | E50: Object-Oriented Software Design | F50: 28 | G50: 27 | H50: 0 | I50: 1 | J50: =ROUND(G50/F50*100,0) -> 96 | K50: Good | L50: Kitaptech University
A51: ATT-0050 | B51: KT-2020-0003 | C51: Omar Haddad | D51: KT-IT201 | E51: Networks & Systems Administration | F51: 30 | G51: 29 | H51: 0 | I51: 1 | J51: =ROUND(G51/F51*100,0) -> 97 | K51: Good | L51: Kitaptech University
A52: ATT-0051 | B52: KT-2020-0004 | C52: Layla Mansour | D52: KT-DS201 | E52: Statistics & Probability for Data Science | F52: 26 | G52: 25 | H52: 0 | I52: 1 | J52: =ROUND(G52/F52*100,0) -> 96 | K52: Good | L52: Kitaptech University
A53: ATT-0052 | B53: KT-2023-0005 | C53: Khalid Nasser | D53: KT-IT201 | E53: Networks & Systems Administration | F53: 27 | G53: 26 | H53: 0 | I53: 1 | J53: =ROUND(G53/F53*100,0) -> 96 | K53: Good | L53: Kitaptech University
A54: ATT-0053 | B54: KT-2021-0006 | C54: Rania Saleh | D54: KT-CS101 | E54: Introduction to Programming | F54: 30 | G54: 29 | H54: 0 | I54: 1 | J54: =ROUND(G54/F54*100,0) -> 97 | K54: Good | L54: Kitaptech University
A55: ATT-0054 | B55: KT-2022-0007 | C55: Hamza Zidane | D55: KT-FT201 | E55: Principles of Financial Technology | F55: 30 | G55: 29 | H55: 0 | I55: 1 | J55: =ROUND(G55/F55*100,0) -> 97 | K55: Good | L55: Kitaptech University
A56: ATT-0055 | B56: KT-2020-0008 | C56: Noor Al-Amin | D56: KT-SE201 | E56: Object-Oriented Software Design | F56: 27 | G56: 26 | H56: 0 | I56: 1 | J56: =ROUND(G56/F56*100,0) -> 96 | K56: Good | L56: Kitaptech University
A57: ATT-0056 | B57: KT-2021-0009 | C57: Bilal Qureshi | D57: KT-DS201 | E57: Statistics & Probability for Data Science | F57: 29 | G57: 28 | H57: 0 | I57: 1 | J57: =ROUND(G57/F57*100,0) -> 97 | K57: Good | L57: Kitaptech University
A58: ATT-0057 | B58: KT-2023-0010 | C58: Sami Hijazi | D58: KT-IT201 | E58: Networks & Systems Administration | F58: 29 | G58: 28 | H58: 0 | I58: 1 | J58: =ROUND(G58/F58*100,0) -> 97 | K58: Good | L58: Kitaptech University
A59: ATT-0058 | B59: KT-2022-0011 | C59: Dalia Abdullah | D59: KT-CS101 | E59: Introduction to Programming | F59: 28 | G59: 27 | H59: 0 | I59: 1 | J59: =ROUND(G59/F59*100,0) -> 96 | K59: Good | L59: Kitaptech University
A60: ATT-0059 | B60: KT-2020-0012 | C60: Tariq Al-Otaibi | D60: KT-SE201 | E60: Object-Oriented Software Design | F60: 26 | G60: 25 | H60: 0 | I60: 1 | J60: =ROUND(G60/F60*100,0) -> 96 | K60: Good | L60: Kitaptech University
... A219: ATT-0218 | B219: TU-PG-2025-0081 | C219: Given Mthembu | D219: MBA602 | E219: Advanced Financial Management | F219: 27 | G219: 16 | H219: 10 | I219: 1 | J219: =ROUND(G219/F219*100,0) -> 59 | K219: At Risk | L219: Templumis University

Sheet Fee Records
A1: Templumis University — Student Fee Records
A2: Academic Year 2023/24 · Semester 1 | All amounts in KES
A4: Fee Record ID | B4: Student ID | C4: Student Name | D4: Programme | E4: Department | F4: Student Type | G4: Current Semester | H4: Sem Fee (KES) | I4: Reg Fee (KES) | J4: Total Billed (KES) | K4: Amount Paid (KES) | L4: Balance (KES) | M4: Fee Status | N4: Institution
A5: FR-0001 | B5: TU-2021-0001 | C5: Amelia Odhiambo | D5: BSc | E5: School of Computing | F5: Undergraduate | G5: Sem 6 | H5: 75000 | I5: 5000 | J5: =H5+I5 -> 80000 | K5: 80000 | L5: =J5-K5 -> 0 | M5: Paid | N5: Templumis University
A6: FR-0002 | B6: TU-2022-0002 | C6: Brian Mwangi | D6: BA | E6: School of Business | F6: Undergraduate | G6: Sem 4 | H6: 65000 | I6: 5000 | J6: =H6+I6 -> 70000 | K6: 70000 | L6: =J6-K6 -> 0 | M6: Paid | N6: Templumis University
A7: FR-0003 | B7: TU-2020-0003 | C7: Claire Nakato | D7: BSc | E7: School of Engineering | F7: Undergraduate | G7: Sem 8 | H7: 75000 | I7: 5000 | J7: =H7+I7 -> 80000 | K7: 80000 | L7: =J7-K7 -> 0 | M7: Paid | N7: Templumis University
A8: FR-0004 | B8: TU-2019-0004 | C8: David Mensah | D8: BSc | E8: School of Health Sciences | F8: Undergraduate | G8: Completed | H8: 75000 | I8: 5000 | J8: =H8+I8 -> 80000 | K8: 80000 | L8: =J8-K8 -> 0 | M8: Paid | N8: Templumis University
A9: FR-0005 | B9: TU-2023-0005 | C9: Esther Wanjiku | D9: BSc | E9: School of Science | F9: Undergraduate | G9: Sem 2 | H9: 75000 | I9: 5000 | J9: =H9+I9 -> 80000 | K9: 45000 | L9: =J9-K9 -> 35000 | M9: Partial | N9: Templumis University
A10: FR-0006 | B10: TU-2021-0006 | C10: Felix Otieno | D10: BEd | E10: School of Education | F10: Undergraduate | G10: Sem 6 | H10: 60000 | I10: 5000 | J10: =H10+I10 -> 65000 | K10: 65000 | L10: =J10-K10 -> 0 | M10: Paid | N10: Templumis University
A11: FR-0007 | B11: TU-2022-0007 | C11: Grace Auma | D11: BSc | E11: School of Science | F11: Undergraduate | G11: Sem 4 | H11: 75000 | I11: 5000 | J11: =H11+I11 -> 80000 | K11: 80000 | L11: =J11-K11 -> 0 | M11: Paid | N11: Templumis University
A12: FR-0008 | B12: TU-2020-0008 | C12: Hassan Abdi | D12: LLB | E12: School of Law | F12: Undergraduate | G12: Sem 8 | H12: 70000 | I12: 5000 | J12: =H12+I12 -> 75000 | K12: 75000 | L12: =J12-K12 -> 0 | M12: Paid | N12: Templumis University
A13: FR-0009 | B13: TU-2021-0009 | C13: Ivy Njeri | D13: BComm | E13: School of Business | F13: Undergraduate | G13: Sem 6 | H13: 65000 | I13: 5000 | J13: =H13+I13 -> 70000 | K13: 0 | L13: =J13-K13 -> 70000 | M13: Deferred | N13: Templumis University
A14: FR-0010 | B14: TU-2023-0010 | C14: James Kibaki | D14: BSc | E14: School of Computing | F14: Undergraduate | G14: Sem 2 | H14: 75000 | I14: 5000 | J14: =H14+I14 -> 80000 | K14: 80000 | L14: =J14-K14 -> 0 | M14: Paid | N14: Templumis University
A15: FR-0011 | B15: TU-2022-0011 | C15: Kezia Moraa | D15: BSc | E15: School of Science | F15: Undergraduate | G15: Sem 4 | H15: 75000 | I15: 5000 | J15: =H15+I15 -> 80000 | K15: 80000 | L15: =J15-K15 -> 0 | M15: Paid | N15: Templumis University
A16: FR-0012 | B16: TU-2019-0012 | C16: Liam Okonkwo | D16: BSc | E16: School of Engineering | F16: Undergraduate | G16: Completed | H16: 75000 | I16: 5000 | J16: =H16+I16 -> 80000 | K16: 80000 | L16: =J16-K16 -> 0 | M16: Paid | N16: Templumis University
... A41: FR-0037 | B41: TU-PG-2023-0037 | C41: Moses Waweru | D41: MSc by Research | E41: School of Computing | F41: Postgraduate | G41: Research Year 1 | H41: 80000 | I41: 5000 | J41: =H41+I41 -> 85000 | K41: 85000 | L41: =J41-K41 -> 0 | M41: Paid | N41: Templumis University
A42: FR-0038 | B42: TU-PHD-2021-0038 | C42: Amina Osei | D42: PhD (Research) | E42: School of Computing | F42: Postgraduate | G42: Research Year 3 | H42: 180000 | I42: 5000 | J42: 185000 | K42: 185000 | L42: 0 | M42: Paid | N42: Templumis University
A43: FR-0039 | B43: TU-PHD-2020-0039 | C43: Samuel Odhiambo | D43: PhD (Research) | E43: School of Health Sciences | F43: Postgraduate | G43: Research Year 4 | H43: 180000 | I43: 5000 | J43: 185000 | K43: 185000 | L43: 0 | M43: Paid | N43: Templumis University
A44: FR-0040 | B44: TU-PHD-2023-0040 | C44: Fatima Al-Rashid | D44: PhD (Research) | E44: School of Business | F44: Postgraduate | G44: Research Year 1 | H44: 180000 | I44: 5000 | J44: 185000 | K44: 185000 | L44: 0 | M44: Paid | N44: Templumis University
A45: FR-0041 | B45: TU-PHD-2022-0041 | C45: Peter Kamau Njeru | D45: PhD (Research) | E45: School of Science | F45: Postgraduate | G45: Research Year 2 | H45: 180000 | I45: 5000 | J45: 185000 | K45: 185000 | L45: 0 | M45: Paid | N45: Templumis University
A46: FR-0042 | B46: KT-2021-0001 | C46: Yusuf Al-Farsi | D46: BSc | E46: School of Computer Science | F46: Undergraduate | G46: Sem 6 | H46: 75000 | I46: 5000 | J46: =H46+I46 -> 80000 | K46: 80000 | L46: =J46-K46 -> 0 | M46: Paid | N46: Kitaptech University
A47: FR-0043 | B47: KT-2022-0002 | C47: Fatima Al-Sayed | D47: BSc | E47: School of Software Engineering | F47: Undergraduate | G47: Sem 4 | H47: 75000 | I47: 5000 | J47: =H47+I47 -> 80000 | K47: 80000 | L47: =J47-K47 -> 0 | M47: Paid | N47: Kitaptech University
A48: FR-0044 | B48: KT-2020-0003 | C48: Omar Haddad | D48: BSc | E48: School of Information Technology & Cybersecurity | F48: Undergraduate | G48: Sem 8 | H48: 75000 | I48: 5000 | J48: =H48+I48 -> 80000 | K48: 80000 | L48: =J48-K48 -> 0 | M48: Paid | N48: Kitaptech University
A49: FR-0045 | B49: KT-2020-0004 | C49: Layla Mansour | D49: BSc | E49: School of Data Science & Artificial Intelligence | F49: Undergraduate | G49: Completed | H49: 75000 | I49: 5000 | J49: =H49+I49 -> 80000 | K49: 80000 | L49: =J49-K49 -> 0 | M49: Cleared | N49: Kitaptech University
A50: FR-0046 | B50: KT-2023-0005 | C50: Khalid Nasser | D50: BSc | E50: School of Information Technology & Cybersecurity | F50: Undergraduate | G50: Sem 2 | H50: 75000 | I50: 5000 | J50: =H50+I50 -> 80000 | K50: 41250 | L50: =J50-K50 -> 38750 | M50: Partial | N50: Kitaptech University
A51: FR-0047 | B51: KT-2021-0006 | C51: Rania Saleh | D51: BSc | E51: School of Computer Science | F51: Undergraduate | G51: Sem 6 | H51: 75000 | I51: 5000 | J51: =H51+I51 -> 80000 | K51: 80000 | L51: =J51-K51 -> 0 | M51: Paid | N51: Kitaptech University
A52: FR-0048 | B52: KT-2022-0007 | C52: Hamza Zidane | D52: BSc | E52: School of Digital Business & Financial Technology | F52: Undergraduate | G52: Sem 4 | H52: 75000 | I52: 5000 | J52: =H52+I52 -> 80000 | K52: 80000 | L52: =J52-K52 -> 0 | M52: Paid | N52: Kitaptech University
A53: FR-0049 | B53: KT-2020-0008 | C53: Noor Al-Amin | D53: BSc | E53: School of Software Engineering | F53: Undergraduate | G53: Sem 8 | H53: 75000 | I53: 5000 | J53: =H53+I53 -> 80000 | K53: 80000 | L53: =J53-K53 -> 0 | M53: Paid | N53: Kitaptech University
A54: FR-0050 | B54: KT-2021-0009 | C54: Bilal Qureshi | D54: BSc | E54: School of Data Science & Artificial Intelligence | F54: Undergraduate | G54: Sem 6 | H54: 75000 | I54: 5000 | J54: =H54+I54 -> 80000 | K54: 0 | L54: =J54-K54 -> 80000 | M54: Deferred | N54: Kitaptech University
